Workbook

Sheet Dashboard
B1: Fincas de boda cerca de Ayala 71 · Madrid
B3: ="Radio "&Notas!B6&" km · "&COUNTA('Fincas 20 km'!B2:B39)&" espacios comparados · datos consultados en octubre de 2026" -> Radio 20 km · 38 espacios comparados · datos consultados en octubre de 2026
B5: ESPACIOS | E5: MÁS CERCANO | H5: MENÚ MEDIO «DESDE» | K5: CATERING LIBRE / LISTA | N5: TIEMPO MEDIO EN COCHE
B6: =COUNTA('Fincas 20 km'!B2:B39) -> 38 | E6: =INDEX('Fincas 20 km'!B2:B39,MATCH(MIN('Fincas 20 km'!F2:F39),'Fincas 20 km'!F2:F39,0)) -> El Jardín de Ventas | H6: =ROUND(AVERAGE('Fincas 20 km'!I2:I39),0) -> 123 | K6: =COUNTIF('Fincas 20 km'!O2:O39,"Posib*")+COUNTIF('Fincas 20 km'!O2:O39,"Proba*")+COUNTIF('Fincas 20 km'!O2:O39,"Lista*") -> 3 | N6: =ROUND(AVERAGE('Fincas 20 km'!AG2:AG39),0) -> 21
B8: dentro del radio | E8: =MIN('Fincas 20 km'!F2:F39)&" km en línea recta" -> 1.3 km en línea recta | H8: ="entre "&MIN('Fincas 20 km'!I2:I39)&" y "&MAX('Fincas 20 km'!I2:I39)&" € por invitado" -> entre 50 y 185 € por invitado | K8: ="de "&COUNTA('Fincas 20 km'!B2:B39)&" · el resto es propio o por consultar" -> de 38 · el resto es propio o por consultar | N8: ="estimado, sin tráfico extra" -> estimado, sin tráfico extra
B10: Precio y tiempo de llegada
B47: Aforo y tipo de catering
J60: Cómo leerlo: casi todos los espacios del radio tienen catering propio, así que el precio «desde» incluye comida. Los minutos son una estimación (distancia × factor carretera ÷ velocidad, ajustables en «Notas»). Pulsa «Ver ruta y tiempo» para abrir Google Maps con el tiempo real a la hora que quieras.
J66: Instagram: no he podido verificar cuentas con seguridad, así que no he escrito ninguna de memoria. En la hoja «Fincas 20 km» (columna AI) pega el @usuario y aquí aparecerá el enlace; mientras tanto, «Buscar en Instagram» abre una búsqueda directa.
B88: Ficha rápida de cada espacio (ordenados de más cerca a más lejos)
B89: Espacio | E89: Km | F89: Min. coche | G89: Menú desde | H89: Aforo máx. | I89: Catering | L89: Nota Google | M89: Instagram | O89: Ruta en vivo | S89: Tipo de catering | T89: Nº
B90: ='Fincas 20 km'!B2 -> El Jardín de Ventas | E90: ='Fincas 20 km'!F2 -> 1.3 | F90: ='Fincas 20 km'!AG2 -> 3 | G90: =IF(ISNUMBER('Fincas 20 km'!I2),'Fincas 20 km'!I2,0) -> 76 | H90: =IF(ISNUMBER('Fincas 20 km'!L2),'Fincas 20 km'!L2,0) -> 0 | I90: =IF(LEFT('Fincas 20 km'!O2,2)="No","Propio / exclusivo",IF(OR(LEFT('Fincas 20 km'!O2,5)="Posib",LEFT('Fincas 20 km'!O2,5)="Proba",LEFT('Fincas 20 km'!O2,5)="Lista",LEFT('Fincas 20 km'!O2,2)="Sí"),"Libre o lista","Por consultar")) -> Propio / exclusivo | L90: =IF(ISNUMBER('Fincas 20 km'!Y2),'Fincas 20 km'!Y2,"—") -> 4.7 | M90: ='Fincas 20 km'!AJ2 -> Buscar en Instagram | O90: ='Fincas 20 km'!AH2 -> Ver ruta y tiempo | S90: Propio / exclusivo | T90: =COUNTIF($I$90:$I$127,S90) -> 31
B91: ='Fincas 20 km'!B3 -> Real Fábrica de Tapices & El Puchero de Plata | E91: ='Fincas 20 km'!F3 -> 2.4 | F91: ='Fincas 20 km'!AG3 -> 5 | G91: =IF(ISNUMBER('Fincas 20 km'!I3),'Fincas 20 km'!I3,0) -> 138 | H91: =IF(ISNUMBER('Fincas 20 km'!L3),'Fincas 20 km'!L3,0) -> 450 | I91: =IF(LEFT('Fincas 20 km'!O3,2)="No","Propio / exclusivo",IF(OR(LEFT('Fincas 20 km'!O3,5)="Posib",LEFT('Fincas 20 km'!O3,5)="Proba",LEFT('Fincas 20 km'!O3,5)="Lista",LEFT('Fincas 20 km'!O3,2)="Sí"),"Libre o lista","Por consultar")) -> Propio / exclusivo | L91: =IF(ISNUMBER('Fincas 20 km'!Y3),'Fincas 20 km'!Y3,"—") -> — | M91: ='Fincas 20 km'!AJ3 -> Buscar en Instagram | O91: ='Fincas 20 km'!AH3 -> Ver ruta y tiempo | S91: Libre o lista | T91: =COUNTIF($I$90:$I$127,S91) -> 3
B92: ='Fincas 20 km'!B4 -> La Quinta by Madrid Catering | E92: ='Fincas 20 km'!F4 -> 3.9 | F92: ='Fincas 20 km'!AG4 -> 8 | G92: =IF(ISNUMBER('Fincas 20 km'!I4),'Fincas 20 km'!I4,0) -> 0 | H92: =IF(ISNUMBER('Fincas 20 km'!L4),'Fincas 20 km'!L4,0) -> 165 | I92: =IF(LEFT('Fincas 20 km'!O4,2)="No","Propio / exclusivo",IF(OR(LEFT('Fincas 20 km'!O4,5)="Posib",LEFT('Fincas 20 km'!O4,5)="Proba",LEFT('Fincas 20 km'!O4,5)="Lista",LEFT('Fincas 20 km'!O4,2)="Sí"),"Libre o lista","Por consultar")) -> Propio / exclusivo | L92: =IF(ISNUMBER('Fincas 20 km'!Y4),'Fincas 20 km'!Y4,"—") -> 4.5 | M92: ='Fincas 20 km'!AJ4 -> Buscar en Instagram | O92: ='Fincas 20 km'!AH4 -> Ver ruta y tiempo | S92: Por consultar | T92: =COUNTIF($I$90:$I$127,S92) -> 4
B93: ='Fincas 20 km'!B5 -> Quinta de los Molinos by Elba | E93: ='Fincas 20 km'!F5 -> 4 | F93: ='Fincas 20 km'!AG5 -> 8 | G93: =IF(ISNUMBER('Fincas 20 km'!I5),'Fincas 20 km'!I5,0) -> 138 | H93: =IF(ISNUMBER('Fincas 20 km'!L5),'Fincas 20 km'!L5,0) -> 0 | I93: =IF(LEFT('Fincas 20 km'!O5,2)="No","Propio / exclusivo",IF(OR(LEFT('Fincas 20 km'!O5,5)="Posib",LEFT('Fincas 20 km'!O5,5)="Proba",LEFT('Fincas 20 km'!O5,5)="Lista",LEFT('Fincas 20 km'!O5,2)="Sí"),"Libre o lista","Por consultar")) -> Propio / exclusivo | L93: =IF(ISNUMBER('Fincas 20 km'!Y5),'Fincas 20 km'!Y5,"—") -> 4.4 | M93: ='Fincas 20 km'!AJ5 -> Buscar en Instagram | O93: ='Fincas 20 km'!AH5 -> Ver ruta y tiempo
B94: ='Fincas 20 km'!B6 -> Palacete / Complejo Duques de Pastrana | E94: ='Fincas 20 km'!F6 -> 4.4 | F94: ='Fincas 20 km'!AG6 -> 9 | G94: =IF(ISNUMBER('Fincas 20 km'!I6),'Fincas 20 km'!I6,0) -> 0 | H94: =IF(ISNUMBER('Fincas 20 km'!L6),'Fincas 20 km'!L6,0) -> 740 | I94: =IF(LEFT('Fincas 20 km'!O6,2)="No","Propio / exclusivo",IF(OR(LEFT('Fincas 20 km'!O6,5)="Posib",LEFT('Fincas 20 km'!O6,5)="Proba",LEFT('Fincas 20 km'!O6,5)="Lista",LEFT('Fincas 20 km'!O6,2)="Sí"),"Libre o lista","Por consultar")) -> Propio / exclusivo | L94: =IF(ISNUMBER('Fincas 20 km'!Y6),'Fincas 20 km'!Y6,"—") -> 4.4 | M94: ='Fincas 20 km'!AJ6 -> Buscar en Instagram | O94: ='Fincas 20 km'!AH6 -> Ver ruta y tiempo
B95: ='Fincas 20 km'!B7 -> Café de Oriente Museo del Traje | E95: ='Fincas 20 km'!F7 -> 4.7 | F95: ='Fincas 20 km'!AG7 -> 9 | G95: =IF(ISNUMBER('Fincas 20 km'!I7),'Fincas 20 km'!I7,0) -> 140 | H95: =IF(ISNUMBER('Fincas 20 km'!L7),'Fincas 20 km'!L7,0) -> 700 | I95: =IF(LEFT('Fincas 20 km'!O7,2)="No","Propio / exclusivo",IF(OR(LEFT('Fincas 20 km'!O7,5)="Posib",LEFT('Fincas 20 km'!O7,5)="Proba",LEFT('Fincas 20 km'!O7,5)="Lista",LEFT('Fincas 20 km'!O7,2)="Sí"),"Libre o lista","Por consultar")) -> Propio / exclusivo | L95: =IF(ISNUMBER('Fincas 20 km'!Y7),'Fincas 20 km'!Y7,"—") -> 4.2 | M95: ='Fincas 20 km'!AJ7 -> Buscar en Instagram | O95: ='Fincas 20 km'!AH7 -> Ver ruta y tiempo
B96: ='Fincas 20 km'!B8 -> Casa de Burgos | E96: ='Fincas 20 km'!F8 -> 4.9 | F96: ='Fincas 20 km'!AG8 -> 10 | G96: =IF(ISNUMBER('Fincas 20 km'!I8),'Fincas 20 km'!I8,0) -> 100 | H96: =IF(ISNUMBER('Fincas 20 km'!L8),'Fincas 20 km'!L8,0) -> 350 | I96: =IF(LEFT('Fincas 20 km'!O8,2)="No","Propio / exclusivo",IF(OR(LEFT('Fincas 20 km'!O8,5)="Posib",LEFT('Fincas 20 km'!O8,5)="Proba",LEFT('Fincas 20 km'!O8,5)="Lista",LEFT('Fincas 20 km'!O8,2)="Sí"),"Libre o lista","Por consultar")) -> Propio / exclusivo | L96: =IF(ISNUMBER('Fincas 20 km'!Y8),'Fincas 20 km'!Y8,"—") -> 4.5 | M96: ='Fincas 20 km'!AJ8 -> Buscar en Instagram | O96: ='Fincas 20 km'!AH8 -> Ver ruta y tiempo
B97: ='Fincas 20 km'!B9 -> La Masía de José Luis | E97: ='Fincas 20 km'!F9 -> 4.9 | F97: ='Fincas 20 km'!AG9 -> 10 | G97: =IF(ISNUMBER('Fincas 20 km'!I9),'Fincas 20 km'!I9,0) -> 140 | H97: =IF(ISNUMBER('Fincas 20 km'!L9),'Fincas 20 km'!L9,0) -> 440 | I97: =IF(LEFT('Fincas 20 km'!O9,2)="No","Propio / exclusivo",IF(OR(LEFT('Fincas 20 km'!O9,5)="Posib",LEFT('Fincas 20 km'!O9,5)="Proba",LEFT('Fincas 20 km'!O9,5)="Lista",LEFT('Fincas 20 km'!O9,2)="Sí"),"Libre o lista","Por consultar")) -> Propio / exclusivo | L97: =IF(ISNUMBER('Fincas 20 km'!Y9),'Fincas 20 km'!Y9,"—") -> 4.5 | M97: ='Fincas 20 km'!AJ9 -> Buscar en Instagram | O97: ='Fincas 20 km'!AH9 -> Ver ruta y tiempo
B98: ='Fincas 20 km'!B10 -> Club de Campo Villa de Madrid | E98: ='Fincas 20 km'!F10 -> 5.8 | F98: ='Fincas 20 km'!AG10 -> 11 | G98: =IF(ISNUMBER('Fincas 20 km'!I10),'Fincas 20 km'!I10,0) -> 0 | H98: =IF(ISNUMBER('Fincas 20 km'!L10),'Fincas 20 km'!L10,0) -> 0 | I98: =IF(LEFT('Fincas 20 km'!O10,2)="No","Propio / exclusivo",IF(OR(LEFT('Fincas 20 km'!O10,5)="Posib",LEFT('Fincas 20 km'!O10,5)="Proba",LEFT('Fincas 20 km'!O10,5)="Lista",LEFT('Fincas 20 km'!O10,2)="Sí"),"Libre o lista","Por consultar")) -> Propio / exclusivo | L98: =IF(ISNUMBER('Fincas 20 km'!Y10),'Fincas 20 km'!Y10,"—") -> 4.3 | M98: ='Fincas 20 km'!AJ10 -> Buscar en Instagram | O98: ='Fincas 20 km'!AH10 -> Ver ruta y tiempo
B99: ='Fincas 20 km'!B11 -> Mirador del Olivar | E99: ='Fincas 20 km'!F11 -> 7.2 | F99: ='Fincas 20 km'!AG11 -> 14 | G99: =IF(ISNUMBER('Fincas 20 km'!I11),'Fincas 20 km'!I11,0) -> 99 | H99: =IF(ISNUMBER('Fincas 20 km'!L11),'Fincas 20 km'!L11,0) -> 520 | I99: =IF(LEFT('Fincas 20 km'!O11,2)="No","Propio / exclusivo",IF(OR(LEFT('Fincas 20 km'!O11,5)="Posib",LEFT('Fincas 20 km'!O11,5)="Proba",LEFT('Fincas 20 km'!O11,5)="Lista",LEFT('Fincas 20 km'!O11,2)="Sí"),"Libre o lista","Por consultar")) -> Propio / exclusivo | L99: =IF(ISNUMBER('Fincas 20 km'!Y11),'Fincas 20 km'!Y11,"—") -> 4.1 | M99: ='Fincas 20 km'!AJ11 -> Buscar en Instagram | O99: ='Fincas 20 km'!AH11 -> Ver ruta y tiempo
B100: ='Fincas 20 km'!B12 -> Club de Tiro de Madrid | E100: ='Fincas 20 km'!F12 -> 8.9 | F100: ='Fincas 20 km'!AG12 -> 17 | G100: =IF(ISNUMBER('Fincas 20 km'!I12),'Fincas 20 km'!I12,0) -> 130 | H100: =IF(ISNUMBER('Fincas 20 km'!L12),'Fincas 20 km'!L12,0) -> 600 | I100: =IF(LEFT('Fincas 20 km'!O12,2)="No","Propio / exclusivo",IF(OR(LEFT('Fincas 20 km'!O12,5)="Posib",LEFT('Fincas 20 km'!O12,5)="Proba",LEFT('Fincas 20 km'!O12,5)="Lista",LEFT('Fincas 20 km'!O12,2)="Sí"),"Libre o lista","Por consultar")) -> Propio / exclusivo | L100: =IF(ISNUMBER('Fincas 20 km'!Y12),'Fincas 20 km'!Y12,"—") -> 4.3 | M100: ='Fincas 20 km'!AJ12 -> Buscar en Instagram | O100: ='Fincas 20 km'!AH12 -> Ver ruta y tiempo
B101: ='Fincas 20 km'!B13 -> Fuentearcos | E101: ='Fincas 20 km'!F13 -> 9.5 | F101: ='Fincas 20 km'!AG13 -> 19 | G101: =IF(ISNUMBER('Fincas 20 km'!I13),'Fincas 20 km'!I13,0) -> 120 | H101: =IF(ISNUMBER('Fincas 20 km'!L13),'Fincas 20 km'!L13,0) -> 350 | I101: =IF(LEFT('Fincas 20 km'!O13,2)="No","Propio / exclusivo",IF(OR(LEFT('Fincas 20 km'!O13,5)="Posib",LEFT('Fincas 20 km'!O13,5)="Proba",LEFT('Fincas 20 km'!O13,5)="Lista",LEFT('Fincas 20 km'!O13,2)="Sí"),"Libre o lista","Por consultar")) -> Propio / exclusivo | L101: =IF(ISNUMBER('Fincas 20 km'!Y13),'Fincas 20 km'!Y13,"—") -> 4.4 | M101: ='Fincas 20 km'!AJ13 -> Buscar en Instagram | O101: ='Fincas 20 km'!AH13 -> Ver ruta y tiempo
B102: ='Fincas 20 km'!B14 -> Finca Solimpar | E102: ='Fincas 20 km'!F14 -> 9.7 | F102: ='Fincas 20 km'!AG14 -> 19 | G102: =IF(ISNUMBER('Fincas 20 km'!I14),'Fincas 20 km'!I14,0) -> 90 | H102: =IF(ISNUMBER('Fincas 20 km'!L14),'Fincas 20 km'!L14,0) -> 300 | I102: =IF(LEFT('Fincas 20 km'!O14,2)="No","Propio / exclusivo",IF(OR(LEFT('Fincas 20 km'!O14,5)="Posib",LEFT('Fincas 20 km'!O14,5)="Proba",LEFT('Fincas 20 km'!O14,5)="Lista",LEFT('Fincas 20 km'!O14,2)="Sí"),"Libre o lista","Por consultar")) -> Propio / exclusivo | L102: =IF(ISNUMBER('Fincas 20 km'!Y14),'Fincas 20 km'!Y14,"—") -> 4.4 | M102: ='Fincas 20 km'!AJ14 -> Buscar en Instagram | O102: ='Fincas 20 km'!AH14 -> Ver ruta y tiempo
B103: ='Fincas 20 km'!B15 -> El Jardín de Somontes (Eventos Somontes) | E103: ='Fincas 20 km'!F15 -> 9.7 | F103: ='Fincas 20 km'!AG15 -> 19 | G103: =IF(ISNUMBER('Fincas 20 km'!I15),'Fincas 20 km'!I15,0) -> 0 | H103: =IF(ISNUMBER('Fincas 20 km'!L15),'Fincas 20 km'!L15,0) -> 400 | I103: =IF(LEFT('Fincas 20 km'!O15,2)="No","Propio / exclusivo",IF(OR(LEFT('Fincas 20 km'!O15,5)="Posib",LEFT('Fincas 20 km'!O15,5)="Proba",LEFT('Fincas 20 km'!O15,5)="Lista",LEFT('Fincas 20 km'!O15,2)="Sí"),"Libre o lista","Por consultar")) -> Libre o lista | L103: =IF(ISNUMBER('Fincas 20 km'!Y15),'Fincas 20 km'!Y15,"—") -> 4.5 | M103: ='Fincas 20 km'!AJ15 -> Buscar en Instagram | O103: ='Fincas 20 km'!AH15 -> Ver ruta y tiempo
B104: ='Fincas 20 km'!B16 -> La Casa de Mónico | E104: ='Fincas 20 km'!F16 -> 9.8 | F104: ='Fincas 20 km'!AG16 -> 19 | G104: =IF(ISNUMBER('Fincas 20 km'!I16),'Fincas 20 km'!I16,0) -> 185 | H104: =IF(ISNUMBER('Fincas 20 km'!L16),'Fincas 20 km'!L16,0) -> 600 | I104: =IF(LEFT('Fincas 20 km'!O16,2)="No","Propio / exclusivo",IF(OR(LEFT('Fincas 20 km'!O16,5)="Posib",LEFT('Fincas 20 km'!O16,5)="Proba",LEFT('Fincas 20 km'!O16,5)="Lista",LEFT('Fincas 20 km'!O16,2)="Sí"),"Libre o lista","Por consultar")) -> Propio / exclusivo | L104: =IF(ISNUMBER('Fincas 20 km'!Y16),'Fincas 20 km'!Y16,"—") -> 4.5 | M104: ='Fincas 20 km'!AJ16 -> Buscar en Instagram | O104: ='Fincas 20 km'!AH16 -> Ver ruta y tiempo
... B127: ='Fincas 20 km'!B39 -> Señorío de Ajuria | E127: ='Fincas 20 km'!F39 -> 19.2 | F127: ='Fincas 20 km'!AG39 -> 37 | G127: =IF(ISNUMBER('Fincas 20 km'!I39),'Fincas 20 km'!I39,0) -> 90 | H127: =IF(ISNUMBER('Fincas 20 km'!L39),'Fincas 20 km'!L39,0) -> 300 | I127: =IF(LEFT('Fincas 20 km'!O39,2)="No","Propio / exclusivo",IF(OR(LEFT('Fincas 20 km'!O39,5)="Posib",LEFT('Fincas 20 km'!O39,5)="Proba",LEFT('Fincas 20 km'!O39,5)="Lista",LEFT('Fincas 20 km'!O39,2)="Sí"),"Libre o lista","Por consultar")) -> Propio / exclusivo | L127: =IF(ISNUMBER('Fincas 20 km'!Y39),'Fincas 20 km'!Y39,"—") -> 4 | M127: ='Fincas 20 km'!AJ39 -> Buscar en Instagram | O127: ='Fincas 20 km'!AH39 -> Ver ruta y tiempo

Sheet Ficha interactiva
B1: Ficha interactiva de finca
B3: Elige una finca en la celda amarilla y cambia los parámetros: todo se recalcula solo. | P3: Datos auxiliares (no tocar)
P4: Precio publicado | Q4: =IF(INDEX('Fincas 20 km'!$I$2:$I$39,$K$5)="","",INDEX('Fincas 20 km'!$I$2:$I$39,$K$5)) -> 76
B5: FINCA ▸ | D5: El Jardín de Ventas | J5: nº en lista | K5: =MATCH($D$5,'Fincas 20 km'!$B$2:$B$39,0) -> 1 | P5: Aforo mín. | Q5: =IF(INDEX('Fincas 20 km'!$K$2:$K$39,$K$5)="","",INDEX('Fincas 20 km'!$K$2:$K$39,$K$5))
P6: Aforo máx. | Q6: =IF(INDEX('Fincas 20 km'!$L$2:$L$39,$K$5)="","",INDEX('Fincas 20 km'!$L$2:$L$39,$K$5))
B7: Tus parámetros (celdas amarillas) | P7: Km en línea recta | Q7: =INDEX('Fincas 20 km'!$F$2:$F$39,$K$5) -> 1.3
B8: Invitados | F8: 120 | H8: IVA (%) | L8: 10 | P8: Precio usado | Q8: =IF(ISNUMBER($F$9),$F$9,$Q$4) -> 76
B9: Precio por invitado (€) · vacío = el publicado | H9: Factor carretera / línea recta | L9: 1.3 | P9: Invitados | Q9: =$F$8 -> 120
B10: Extras por invitado (€) · barra libre extra, recena… | F10: 0 | H10: Velocidad media (km/h) | L10: 40 | P10: Minutos elegida | Q10: =ROUND($Q$7*$L$9/$L$10*60,0) -> 3
B11: Costes fijos (€) · alquiler, DJ, flores… | F11: 0 | P11: Menú elegida (usado) | Q11: =IF(ISNUMBER($Q$8),$Q$8,NA()) -> 76
P12: Finca | Q12: Minutos | R12: Menú desde | T12: Total (otras) | U12: Total (elegida)
B13: COSTE TOTAL ESTIMADO | E13: POR INVITADO | H13: EN COCHE (ESTIM.) | K13: DISTANCIA EN LÍNEA RECTA | P13: ='Fincas 20 km'!B2 -> El Jardín de Ventas | Q13: =ROUND('Fincas 20 km'!F2*$L$9/$L$10*60,0) -> 3 | R13: =IF('Fincas 20 km'!I2="",NA(),'Fincas 20 km'!I2) -> 76 | T13: =IF($P13=$D$5,0,IF(ISNUMBER(R13),(IF(AND($P13=$D$5,ISNUMBER($F$9)),$F$9,R13)*$F$8+$F$8*$F$10+$F$11)*(1+$L$8/100),0)) -> 0 | U13: =IF($P13=$D$5,IF(ISNUMBER(R13),(IF(AND($P13=$D$5,ISNUMBER($F$9)),$F$9,R13)*$F$8+$F$8*$F$10+$F$11)*(1+$L$8/100),0),0) -> 10032
B14: =IF(ISNUMBER($F$22),$F$22,"—") -> 10032 | E14: =IF(ISNUMBER($F$22),$F$22/$F$8,"—") -> 83.6 | H14: =ROUND($Q$7*$L$9/$L$10*60,0) -> 3 | K14: =$Q$7 -> 1.3 | P14: ='Fincas 20 km'!B3 -> Real Fábrica de Tapices & El Puchero de Plata | Q14: =ROUND('Fincas 20 km'!F3*$L$9/$L$10*60,0) -> 5 | R14: =IF('Fincas 20 km'!I3="",NA(),'Fincas 20 km'!I3) -> 138 | T14: =IF($P14=$D$5,0,IF(ISNUMBER(R14),(IF(AND($P14=$D$5,ISNUMBER($F$9)),$F$9,R14)*$F$8+$F$8*$F$10+$F$11)*(1+$L$8/100),0)) -> 18216 | U14: =IF($P14=$D$5,IF(ISNUMBER(R14),(IF(AND($P14=$D$5,ISNUMBER($F$9)),$F$9,R14)*$F$8+$F$8*$F$10+$F$11)*(1+$L$8/100),0),0) -> 0
P15: ='Fincas 20 km'!B4 -> La Quinta by Madrid Catering | Q15: =ROUND('Fincas 20 km'!F4*$L$9/$L$10*60,0) -> 8 | R15: =IF('Fincas 20 km'!I4="",NA(),'Fincas 20 km'!I4) -> #N/A | T15: =IF($P15=$D$5,0,IF(ISNUMBER(R15),(IF(AND($P15=$D$5,ISNUMBER($F$9)),$F$9,R15)*$F$8+$F$8*$F$10+$F$11)*(1+$L$8/100),0)) -> 0 | U15: =IF($P15=$D$5,IF(ISNUMBER(R15),(IF(AND($P15=$D$5,ISNUMBER($F$9)),$F$9,R15)*$F$8+$F$8*$F$10+$F$11)*(1+$L$8/100),0),0) -> 0
B16: =IF(ISNUMBER($F$22),$F$8&" invitados × "&TEXT($Q$8,"#,##0")&" € + extras, fijos e IVA","Sin precio publicado: escribe el tuyo arriba") -> 120 invitados × 76 € + extras, fijos e IVA | E16: ="con IVA del "&$L$8&" %" -> con IVA del 10 % | H16: ="a "&$L$10&" km/h, factor "&TEXT($L$9,"0.0") -> a 40 km/h, factor 1.3 | K16: mismo dato que el Excel | P16: ='Fincas 20 km'!B5 -> Quinta de los Molinos by Elba | Q16: =ROUND('Fincas 20 km'!F5*$L$9/$L$10*60,0) -> 8 | R16: =IF('Fincas 20 km'!I5="",NA(),'Fincas 20 km'!I5) -> 138 | T16: =IF($P16=$D$5,0,IF(ISNUMBER(R16),(IF(AND($P16=$D$5,ISNUMBER($F$9)),$F$9,R16)*$F$8+$F$8*$F$10+$F$11)*(1+$L$8/100),0)) -> 18216 | U16: =IF($P16=$D$5,IF(ISNUMBER(R16),(IF(AND($P16=$D$5,ISNUMBER($F$9)),$F$9,R16)*$F$8+$F$8*$F$10+$F$11)*(1+$L$8/100),0),0) -> 0
P17: ='Fincas 20 km'!B6 -> Palacete / Complejo Duques de Pastrana | Q17: =ROUND('Fincas 20 km'!F6*$L$9/$L$10*60,0) -> 9 | R17: =IF('Fincas 20 km'!I6="",NA(),'Fincas 20 km'!I6) -> #N/A | T17: =IF($P17=$D$5,0,IF(ISNUMBER(R17),(IF(AND($P17=$D$5,ISNUMBER($F$9)),$F$9,R17)*$F$8+$F$8*$F$10+$F$11)*(1+$L$8/100),0)) -> 0 | U17: =IF($P17=$D$5,IF(ISNUMBER(R17),(IF(AND($P17=$D$5,ISNUMBER($F$9)),$F$9,R17)*$F$8+$F$8*$F$10+$F$11)*(1+$L$8/100),0),0) -> 0
B18: Desglose del coste | P18: ='Fincas 20 km'!B7 -> Café de Oriente Museo del Traje | Q18: =ROUND('Fincas 20 km'!F7*$L$9/$L$10*60,0) -> 9 | R18: =IF('Fincas 20 km'!I7="",NA(),'Fincas 20 km'!I7) -> 140 | T18: =IF($P18=$D$5,0,IF(ISNUMBER(R18),(IF(AND($P18=$D$5,ISNUMBER($F$9)),$F$9,R18)*$F$8+$F$8*$F$10+$F$11)*(1+$L$8/100),0)) -> 18480 | U18: =IF($P18=$D$5,IF(ISNUMBER(R18),(IF(AND($P18=$D$5,ISNUMBER($F$9)),$F$9,R18)*$F$8+$F$8*$F$10+$F$11)*(1+$L$8/100),0),0) -> 0
B19: Menú (invitados × precio) | F19: =IF(ISNUMBER($Q$8),$F$8*$Q$8,"") -> 9120 | G19: =IF(ISNUMBER($F$22),F19/$F$22,"") -> 0.90909091 | P19: ='Fincas 20 km'!B8 -> Casa de Burgos | Q19: =ROUND('Fincas 20 km'!F8*$L$9/$L$10*60,0) -> 10 | R19: =IF('Fincas 20 km'!I8="",NA(),'Fincas 20 km'!I8) -> 100 | T19: =IF($P19=$D$5,0,IF(ISNUMBER(R19),(IF(AND($P19=$D$5,ISNUMBER($F$9)),$F$9,R19)*$F$8+$F$8*$F$10+$F$11)*(1+$L$8/100),0)) -> 13200 | U19: =IF($P19=$D$5,IF(ISNUMBER(R19),(IF(AND($P19=$D$5,ISNUMBER($F$9)),$F$9,R19)*$F$8+$F$8*$F$10+$F$11)*(1+$L$8/100),0),0) -> 0
B20: Extras | F20: =IF(ISNUMBER($Q$8),$F$8*$F$10,"") -> 0 | G20: =IF(ISNUMBER($F$22),F20/$F$22,"") -> 0 | P20: ='Fincas 20 km'!B9 -> La Masía de José Luis | Q20: =ROUND('Fincas 20 km'!F9*$L$9/$L$10*60,0) -> 10 | R20: =IF('Fincas 20 km'!I9="",NA(),'Fincas 20 km'!I9) -> 140 | T20: =IF($P20=$D$5,0,IF(ISNUMBER(R20),(IF(AND($P20=$D$5,ISNUMBER($F$9)),$F$9,R20)*$F$8+$F$8*$F$10+$F$11)*(1+$L$8/100),0)) -> 18480 | U20: =IF($P20=$D$5,IF(ISNUMBER(R20),(IF(AND($P20=$D$5,ISNUMBER($F$9)),$F$9,R20)*$F$8+$F$8*$F$10+$F$11)*(1+$L$8/100),0),0) -> 0
B21: Costes fijos | F21: =IF(ISNUMBER($Q$8),$F$11,"") -> 0 | G21: =IF(ISNUMBER($F$22),F21/$F$22,"") -> 0 | P21: ='Fincas 20 km'!B10 -> Club de Campo Villa de Madrid | Q21: =ROUND('Fincas 20 km'!F10*$L$9/$L$10*60,0) -> 11 | R21: =IF('Fincas 20 km'!I10="",NA(),'Fincas 20 km'!I10) -> #N/A | T21: =IF($P21=$D$5,0,IF(ISNUMBER(R21),(IF(AND($P21=$D$5,ISNUMBER($F$9)),$F$9,R21)*$F$8+$F$8*$F$10+$F$11)*(1+$L$8/100),0)) -> 0 | U21: =IF($P21=$D$5,IF(ISNUMBER(R21),(IF(AND($P21=$D$5,ISNUMBER($F$9)),$F$9,R21)*$F$8+$F$8*$F$10+$F$11)*(1+$L$8/100),0),0) -> 0
B22: TOTAL (con IVA) | F22: =IF(ISNUMBER($Q$8),SUM($F$19:$F$21)+$F$23,"") -> 10032 | G22: =IF(ISNUMBER($F$22),F22/$F$22,"") -> 1 | P22: ='Fincas 20 km'!B11 -> Mirador del Olivar | Q22: =ROUND('Fincas 20 km'!F11*$L$9/$L$10*60,0) -> 14 | R22: =IF('Fincas 20 km'!I11="",NA(),'Fincas 20 km'!I11) -> 99 | T22: =IF($P22=$D$5,0,IF(ISNUMBER(R22),(IF(AND($P22=$D$5,ISNUMBER($F$9)),$F$9,R22)*$F$8+$F$8*$F$10+$F$11)*(1+$L$8/100),0)) -> 13068 | U22: =IF($P22=$D$5,IF(ISNUMBER(R22),(IF(AND($P22=$D$5,ISNUMBER($F$9)),$F$9,R22)*$F$8+$F$8*$F$10+$F$11)*(1+$L$8/100),0),0) -> 0
B23: de los cuales, IVA | F23: =IF(ISNUMBER($Q$8),SUM($F$19:$F$21)*$L$8/100,"") -> 912 | G23: =IF(ISNUMBER($F$22),F23/$F$22,"") -> 0.090909091 | P23: ='Fincas 20 km'!B12 -> Club de Tiro de Madrid | Q23: =ROUND('Fincas 20 km'!F12*$L$9/$L$10*60,0) -> 17 | R23: =IF('Fincas 20 km'!I12="",NA(),'Fincas 20 km'!I12) -> 130 | T23: =IF($P23=$D$5,0,IF(ISNUMBER(R23),(IF(AND($P23=$D$5,ISNUMBER($F$9)),$F$9,R23)*$F$8+$F$8*$F$10+$F$11)*(1+$L$8/100),0)) -> 17160 | U23: =IF($P23=$D$5,IF(ISNUMBER(R23),(IF(AND($P23=$D$5,ISNUMBER($F$9)),$F$9,R23)*$F$8+$F$8*$F$10+$F$11)*(1+$L$8/100),0),0) -> 0
P24: ='Fincas 20 km'!B13 -> Fuentearcos | Q24: =ROUND('Fincas 20 km'!F13*$L$9/$L$10*60,0) -> 19 | R24: =IF('Fincas 20 km'!I13="",NA(),'Fincas 20 km'!I13) -> 120 | T24: =IF($P24=$D$5,0,IF(ISNUMBER(R24),(IF(AND($P24=$D$5,ISNUMBER($F$9)),$F$9,R24)*$F$8+$F$8*$F$10+$F$11)*(1+$L$8/100),0)) -> 15840 | U24: =IF($P24=$D$5,IF(ISNUMBER(R24),(IF(AND($P24=$D$5,ISNUMBER($F$9)),$F$9,R24)*$F$8+$F$8*$F$10+$F$11)*(1+$L$8/100),0),0) -> 0
B25: =IF(NOT(ISNUMBER($Q$8)),"⚠ Esta finca no publica precio: escribe tu estimación en «Precio por invitado».","") | P25: ='Fincas 20 km'!B14 -> Finca Solimpar | Q25: =ROUND('Fincas 20 km'!F14*$L$9/$L$10*60,0) -> 19 | R25: =IF('Fincas 20 km'!I14="",NA(),'Fincas 20 km'!I14) -> 90 | T25: =IF($P25=$D$5,0,IF(ISNUMBER(R25),(IF(AND($P25=$D$5,ISNUMBER($F$9)),$F$9,R25)*$F$8+$F$8*$F$10+$F$11)*(1+$L$8/100),0)) -> 11880 | U25: =IF($P25=$D$5,IF(ISNUMBER(R25),(IF(AND($P25=$D$5,ISNUMBER($F$9)),$F$9,R25)*$F$8+$F$8*$F$10+$F$11)*(1+$L$8/100),0),0) -> 0
B26: =IF(AND(ISNUMBER($Q$5),$F$8<$Q$5),"⚠ Con "&$F$8&" invitados quedas por debajo del mínimo habitual ("&$Q$5&"): suelen cobrar la diferencia.","") | P26: ='Fincas 20 km'!B15 -> El Jardín de Somontes (Eventos Somontes) | Q26: =ROUND('Fincas 20 km'!F15*$L$9/$L$10*60,0) -> 19 | R26: =IF('Fincas 20 km'!I15="",NA(),'Fincas 20 km'!I15) -> #N/A | T26: =IF($P26=$D$5,0,IF(ISNUMBER(R26),(IF(AND($P26=$D$5,ISNUMBER($F$9)),$F$9,R26)*$F$8+$F$8*$F$10+$F$11)*(1+$L$8/100),0)) -> 0 | U26: =IF($P26=$D$5,IF(ISNUMBER(R26),(IF(AND($P26=$D$5,ISNUMBER($F$9)),$F$9,R26)*$F$8+$F$8*$F$10+$F$11)*(1+$L$8/100),0),0) -> 0
B27: =IF(AND(ISNUMBER($Q$6),$F$8>$Q$6),"⛔ Con "&$F$8&" invitados superas el aforo máximo publicado ("&$Q$6&").","") | P27: ='Fincas 20 km'!B16 -> La Casa de Mónico | Q27: =ROUND('Fincas 20 km'!F16*$L$9/$L$10*60,0) -> 19 | R27: =IF('Fincas 20 km'!I16="",NA(),'Fincas 20 km'!I16) -> 185 | T27: =IF($P27=$D$5,0,IF(ISNUMBER(R27),(IF(AND($P27=$D$5,ISNUMBER($F$9)),$F$9,R27)*$F$8+$F$8*$F$10+$F$11)*(1+$L$8/100),0)) -> 24420 | U27: =IF($P27=$D$5,IF(ISNUMBER(R27),(IF(AND($P27=$D$5,ISNUMBER($F$9)),$F$9,R27)*$F$8+$F$8*$F$10+$F$11)*(1+$L$8/100),0),0) -> 0
B28: =IF(AND(ISNUMBER($Q$6),$F$8<=$Q$6,OR(NOT(ISNUMBER($Q$5)),$F$8>=$Q$5)),"✓ Tus invitados caben dentro del aforo publicado.","") | P28: ='Fincas 20 km'!B17 -> Finca La Gaivota | Q28: =ROUND('Fincas 20 km'!F17*$L$9/$L$10*60,0) -> 19 | R28: =IF('Fincas 20 km'!I17="",NA(),'Fincas 20 km'!I17) -> #N/A | T28: =IF($P28=$D$5,0,IF(ISNUMBER(R28),(IF(AND($P28=$D$5,ISNUMBER($F$9)),$F$9,R28)*$F$8+$F$8*$F$10+$F$11)*(1+$L$8/100),0)) -> 0 | U28: =IF($P28=$D$5,IF(ISNUMBER(R28),(IF(AND($P28=$D$5,ISNUMBER($F$9)),$F$9,R28)*$F$8+$F$8*$F$10+$F$11)*(1+$L$8/100),0),0) -> 0
B29: =IF(ISNUMBER(SEARCH("mínim",INDEX('Fincas 20 km'!$H$2:$H$39,$K$5))),"⚠ El precio publicado menciona un mínimo de facturación: léelo completo en «Precio publicado».","") -> ⚠ El precio publicado menciona un mínimo de facturación: léelo completo en «Precio publicado». | P29: ='Fincas 20 km'!B18 -> Finca Astilbe (by Eneldo) | Q29: =ROUND('Fincas 20 km'!F18*$L$9/$L$10*60,0) -> 21 | R29: =IF('Fincas 20 km'!I18="",NA(),'Fincas 20 km'!I18) -> 145 | T29: =IF($P29=$D$5,0,IF(ISNUMBER(R29),(IF(AND($P29=$D$5,ISNUMBER($F$9)),$F$9,R29)*$F$8+$F$8*$F$10+$F$11)*(1+$L$8/100),0)) -> 19140 | U29: =IF($P29=$D$5,IF(ISNUMBER(R29),(IF(AND($P29=$D$5,ISNUMBER($F$9)),$F$9,R29)*$F$8+$F$8*$F$10+$F$11)*(1+$L$8/100),0),0) -> 0
P30: ='Fincas 20 km'!B19 -> El Mirador de Cuatrovientos (incl. Finca Las Palmeras) | Q30: =ROUND('Fincas 20 km'!F19*$L$9/$L$10*60,0) -> 21 | R30: =IF('Fincas 20 km'!I19="",NA(),'Fincas 20 km'!I19) -> 99 | T30: =IF($P30=$D$5,0,IF(ISNUMBER(R30),(IF(AND($P30=$D$5,ISNUMBER($F$9)),$F$9,R30)*$F$8+$F$8*$F$10+$F$11)*(1+$L$8/100),0)) -> 13068 | U30: =IF($P30=$D$5,IF(ISNUMBER(R30),(IF(AND($P30=$D$5,ISNUMBER($F$9)),$F$9,R30)*$F$8+$F$8*$F$10+$F$11)*(1+$L$8/100),0),0) -> 0
B31: Ficha de la finca | P31: ='Fincas 20 km'!B20 -> U-Zalacaín La Finca | Q31: =ROUND('Fincas 20 km'!F20*$L$9/$L$10*60,0) -> 21 | R31: =IF('Fincas 20 km'!I20="",NA(),'Fincas 20 km'!I20) -> 135 | T31: =IF($P31=$D$5,0,IF(ISNUMBER(R31),(IF(AND($P31=$D$5,ISNUMBER($F$9)),$F$9,R31)*$F$8+$F$8*$F$10+$F$11)*(1+$L$8/100),0)) -> 17820 | U31: =IF($P31=$D$5,IF(ISNUMBER(R31),(IF(AND($P31=$D$5,ISNUMBER($F$9)),$F$9,R31)*$F$8+$F$8*$F$10+$F$11)*(1+$L$8/100),0),0) -> 0
B32: Tipo de espacio | E32: =IFERROR(IF(INDEX('Fincas 20 km'!$C$2:$C$39,$K$5)="","No consta",INDEX('Fincas 20 km'!$C$2:$C$39,$K$5)),"—") -> Jardín del hotel NH Madrid Ventas | P32: ='Fincas 20 km'!B21 -> Finca La Muñoza (La Cococha) | Q32: =ROUND('Fincas 20 km'!F21*$L$9/$L$10*60,0) -> 21 | R32: =IF('Fincas 20 km'!I21="",NA(),'Fincas 20 km'!I21) -> 125 | T32: =IF($P32=$D$5,0,IF(ISNUMBER(R32),(IF(AND($P32=$D$5,ISNUMBER($F$9)),$F$9,R32)*$F$8+$F$8*$F$10+$F$11)*(1+$L$8/100),0)) -> 16500 | U32: =IF($P32=$D$5,IF(ISNUMBER(R32),(IF(AND($P32=$D$5,ISNUMBER($F$9)),$F$9,R32)*$F$8+$F$8*$F$10+$F$11)*(1+$L$8/100),0),0) -> 0
B33: Zona | E33: =IFERROR(IF(INDEX('Fincas 20 km'!$D$2:$D$39,$K$5)="","No consta",INDEX('Fincas 20 km'!$D$2:$D$39,$K$5)),"—") -> Madrid – Ventas (Salamanca) | P33: ='Fincas 20 km'!B22 -> Real Club La Moraleja | Q33: =ROUND('Fincas 20 km'!F22*$L$9/$L$10*60,0) -> 22 | R33: =IF('Fincas 20 km'!I22="",NA(),'Fincas 20 km'!I22) -> #N/A | T33: =IF($P33=$D$5,0,IF(ISNUMBER(R33),(IF(AND($P33=$D$5,ISNUMBER($F$9)),$F$9,R33)*$F$8+$F$8*$F$10+$F$11)*(1+$L$8/100),0)) -> 0 | U33: =IF($P33=$D$5,IF(ISNUMBER(R33),(IF(AND($P33=$D$5,ISNUMBER($F$9)),$F$9,R33)*$F$8+$F$8*$F$10+$F$11)*(1+$L$8/100),0),0) -> 0
B34: Dirección | E34: =IFERROR(IF(INDEX('Fincas 20 km'!$E$2:$E$39,$K$5)="","No consta",INDEX('Fincas 20 km'!$E$2:$E$39,$K$5)),"—") -> C/ de Biarritz 2, 28028 Madrid | P34: ='Fincas 20 km'!B23 -> Finca Petit Moraleja | Q34: =ROUND('Fincas 20 km'!F23*$L$9/$L$10*60,0) -> 24 | R34: =IF('Fincas 20 km'!I23="",NA(),'Fincas 20 km'!I23) -> #N/A | T34: =IF($P34=$D$5,0,IF(ISNUMBER(R34),(IF(AND($P34=$D$5,ISNUMBER($F$9)),$F$9,R34)*$F$8+$F$8*$F$10+$F$11)*(1+$L$8/100),0)) -> 0 | U34: =IF($P34=$D$5,IF(ISNUMBER(R34),(IF(AND($P34=$D$5,ISNUMBER($F$9)),$F$9,R34)*$F$8+$F$8*$F$10+$F$11)*(1+$L$8/100),0),0) -> 0
B35: Aforo | E35: =IFERROR(IF(INDEX('Fincas 20 km'!$M$2:$M$39,$K$5)="","No consta",INDEX('Fincas 20 km'!$M$2:$M$39,$K$5)),"—") -> No publicado | P35: ='Fincas 20 km'!B24 -> El Jardín de la Florida | Q35: =ROUND('Fincas 20 km'!F24*$L$9/$L$10*60,0) -> 25 | R35: =IF('Fincas 20 km'!I24="",NA(),'Fincas 20 km'!I24) -> #N/A | T35: =IF($P35=$D$5,0,IF(ISNUMBER(R35),(IF(AND($P35=$D$5,ISNUMBER($F$9)),$F$9,R35)*$F$8+$F$8*$F$10+$F$11)*(1+$L$8/100),0)) -> 0 | U35: =IF($P35=$D$5,IF(ISNUMBER(R35),(IF(AND($P35=$D$5,ISNUMBER($F$9)),$F$9,R35)*$F$8+$F$8*$F$10+$F$11)*(1+$L$8/100),0),0) -> 0
B36: Catering (quién lo da) | E36: =IFERROR(IF(INDEX('Fincas 20 km'!$N$2:$N$39,$K$5)="","No consta",INDEX('Fincas 20 km'!$N$2:$N$39,$K$5)),"—") -> Cocina del hotel NH Ventas | P36: ='Fincas 20 km'!B25 -> Initium (Artigot Catering) | Q36: =ROUND('Fincas 20 km'!F25*$L$9/$L$10*60,0) -> 25 | R36: =IF('Fincas 20 km'!I25="",NA(),'Fincas 20 km'!I25) -> 150 | T36: =IF($P36=$D$5,0,IF(ISNUMBER(R36),(IF(AND($P36=$D$5,ISNUMBER($F$9)),$F$9,R36)*$F$8+$F$8*$F$10+$F$11)*(1+$L$8/100),0)) -> 19800 | U36: =IF($P36=$D$5,IF(ISNUMBER(R36),(IF(AND($P36=$D$5,ISNUMBER($F$9)),$F$9,R36)*$F$8+$F$8*$F$10+$F$11)*(1+$L$8/100),0),0) -> 0
B37: ¿Catering libre? | E37: =IFERROR(IF(INDEX('Fincas 20 km'!$O$2:$O$39,$K$5)="","No consta",INDEX('Fincas 20 km'!$O$2:$O$39,$K$5)),"—") -> No (catering del hotel); tarta propia permitida | P37: ='Fincas 20 km'!B26 -> Finca El Chaparral | Q37: =ROUND('Fincas 20 km'!F26*$L$9/$L$10*60,0) -> 25 | R37: =IF('Fincas 20 km'!I26="",NA(),'Fincas 20 km'!I26) -> #N/A | T37: =IF($P37=$D$5,0,IF(ISNUMBER(R37),(IF(AND($P37=$D$5,ISNUMBER($F$9)),$F$9,R37)*$F$8+$F$8*$F$10+$F$11)*(1+$L$8/100),0)) -> 0 | U37: =IF($P37=$D$5,IF(ISNUMBER(R37),(IF(AND($P37=$D$5,ISNUMBER($F$9)),$F$9,R37)*$F$8+$F$8*$F$10+$F$11)*(1+$L$8/100),0),0) -> 0
B38: Salones y espacios | E38: =IFERROR(IF(INDEX('Fincas 20 km'!$P$2:$P$39,$K$5)="","No consta",INDEX('Fincas 20 km'!$P$2:$P$39,$K$5)),"—") -> Jardín (ceremonia civil y cóctel) + terraza reformada + salón del hotel; banquete también al aire libre | P38: ='Fincas 20 km'!B27 -> Torzares (finca La Escorzonera) | Q38: =ROUND('Fincas 20 km'!F27*$L$9/$L$10*60,0) -> 27 | R38: =IF('Fincas 20 km'!I27="",NA(),'Fincas 20 km'!I27) -> #N/A | T38: =IF($P38=$D$5,0,IF(ISNUMBER(R38),(IF(AND($P38=$D$5,ISNUMBER($F$9)),$F$9,R38)*$F$8+$F$8*$F$10+$F$11)*(1+$L$8/100),0)) -> 0 | U38: =IF($P38=$D$5,IF(ISNUMBER(R38),(IF(AND($P38=$D$5,ISNUMBER($F$9)),$F$9,R38)*$F$8+$F$8*$F$10+$F$11)*(1+$L$8/100),0),0) -> 0
B39: ¿Un salón o varios? | E39: =IFERROR(IF(INDEX('Fincas 20 km'!$Q$2:$Q$39,$K$5)="","No consta",INDEX('Fincas 20 km'!$Q$2:$Q$39,$K$5)),"—") -> Varios | P39: ='Fincas 20 km'!B28 -> Restaurante San Francisco (El Pardo) | Q39: =ROUND('Fincas 20 km'!F28*$L$9/$L$10*60,0) -> 27 | R39: =IF('Fincas 20 km'!I28="",NA(),'Fincas 20 km'!I28) -> #N/A | T39: =IF($P39=$D$5,0,IF(ISNUMBER(R39),(IF(AND($P39=$D$5,ISNUMBER($F$9)),$F$9,R39)*$F$8+$F$8*$F$10+$F$11)*(1+$L$8/100),0)) -> 0 | U39: =IF($P39=$D$5,IF(ISNUMBER(R39),(IF(AND($P39=$D$5,ISNUMBER($F$9)),$F$9,R39)*$F$8+$F$8*$F$10+$F$11)*(1+$L$8/100),0),0) -> 0
B40: Terraza / jardín | E40: =IFERROR(IF(INDEX('Fincas 20 km'!$R$2:$R$39,$K$5)="","No consta",INDEX('Fincas 20 km'!$R$2:$R$39,$K$5)),"—") -> Sí (jardín y terraza recién reformada) | P40: ='Fincas 20 km'!B29 -> Palacio del Negralejo (Grupo Negralejo) | Q40: =ROUND('Fincas 20 km'!F29*$L$9/$L$10*60,0) -> 27 | R40: =IF('Fincas 20 km'!I29="",NA(),'Fincas 20 km'!I29) -> 150 | T40: =IF($P40=$D$5,0,IF(ISNUMBER(R40),(IF(AND($P40=$D$5,ISNUMBER($F$9)),$F$9,R40)*$F$8+$F$8*$F$10+$F$11)*(1+$L$8/100),0)) -> 19800 | U40: =IF($P40=$D$5,IF(ISNUMBER(R40),(IF(AND($P40=$D$5,ISNUMBER($F$9)),$F$9,R40)*$F$8+$F$8*$F$10+$F$11)*(1+$L$8/100),0),0) -> 0
B41: Cuarto o zona de novios | E41: =IFERROR(IF(INDEX('Fincas 20 km'!$S$2:$S$39,$K$5)="","No consta",INDEX('Fincas 20 km'!$S$2:$S$39,$K$5)),"—") -> Sí – habitaciones del hotel | P41: ='Fincas 20 km'!B30 -> Jardines del Negralejo (Grupo Negralejo) | Q41: =ROUND('Fincas 20 km'!F30*$L$9/$L$10*60,0) -> 27 | R41: =IF('Fincas 20 km'!I30="",NA(),'Fincas 20 km'!I30) -> 150 | T41: =IF($P41=$D$5,0,IF(ISNUMBER(R41),(IF(AND($P41=$D$5,ISNUMBER($F$9)),$F$9,R41)*$F$8+$F$8*$F$10+$F$11)*(1+$L$8/100),0)) -> 19800 | U41: =IF($P41=$D$5,IF(ISNUMBER(R41),(IF(AND($P41=$D$5,ISNUMBER($F$9)),$F$9,R41)*$F$8+$F$8*$F$10+$F$11)*(1+$L$8/100),0),0) -> 0
...

Sheet Fincas 20 km
A1: Nº | B1: Nombre | C1: Tipo de espacio | D1: Zona / municipio | E1: Dirección | F1: Distancia en línea recta (km) | G1: ¿Dentro del radio? | H1: Precio orientativo | I1: Precio menú desde (€/invitado) | J1: ="Coste menú orientativo para "&Notas!$B$7&" invitados (€)" -> Coste menú orientativo para 120 invitados (€) | K1: Aforo mín. | L1: Aforo máx. | M1: Aforo (detalle) | N1: Catering (quién lo da) | O1: ¿Catering libre? | P1: Salones / espacios | Q1: ¿Un salón o varios? | R1: Terraza / jardín | S1: Cuarto o zona de novios | T1: Ceremonia en la finca | U1: Alojamiento | V1: Parking | W1: Horario / nº eventos | X1: Observaciones | Y1: Google (nota) | Z1: Google (nº reseñas) | AA1: bodas.net (nota y opiniones) | AB1: Teléfono | AC1: Fuente principal | AD1: Ver en Google Maps | AE1: Latitud | AF1: Longitud | AG1: Tiempo estimado en coche (min) | AH1: Ruta en Google Maps (tiempo real) | AI1: Instagram (@usuario) | AJ1: Instagram: abrir / buscar
A2: 1 | B2: El Jardín de Ventas | C2: Jardín del hotel NH Madrid Ventas | D2: Madrid – Ventas (Salamanca) | E2: C/ de Biarritz 2, 28028 Madrid | F2: =ROUND(6371*2*ASIN(SQRT(SIN(RADIANS(AE2-Notas!$B$4)/2)^2+COS(RADIANS(Notas!$B$4))*COS(RADIANS(AE2))*SIN(RADIANS(AF2-Notas!$B$5)/2)^2)),1) -> 1.3 | G2: =IF(F2<=Notas!$B$6,"Sí","No") -> Sí | H2: Menú desde 76 € (promoción bodas.net); facturación mínima 9.000 € | I2: 76 | J2: =IF(ISNUMBER(I2),I2*Notas!$B$7,"") -> 9120 | M2: No publicado | N2: Cocina del hotel NH Ventas | O2: No (catering del hotel); tarta propia permitida | P2: Jardín (ceremonia civil y cóctel) + terraza reformada + salón del hotel; banquete también al aire libre | Q2: Varios | R2: Sí (jardín y terraza recién reformada) | S2: Sí – habitaciones del hotel | T2: Sí | U2: Sí (hotel NH) | V2: No consta | W2: No consta | X2: El más céntrico de la lista (evita autobús). Opiniones destacan al wedding planner (Roberto) y que es LGTBI+ y vegan friendly. | Y2: 4.7 | Z2: 15 | AA2: 4,9 (161) | AB2: +34 913 61 02 88 | AC2: https://www.bodas.net/hoteles/jardin-de-ventas--e7903 | AD2: =HYPERLINK("https://www.google.com/maps/search/?api=1&query="&AE2&","&AF2,"Abrir mapa") -> Abrir mapa | AE2: 40.435353 | AF2: -3.6638616 | AG2: =ROUND(F2*Notas!$B$8/Notas!$B$9*60,0) -> 3 | AH2: =HYPERLINK("https://www.google.com/maps/dir/?api=1&origin=Calle+de+Ayala+71,+Madrid&destination="&AE2&","&AF2&"&travelmode=driving","Ver ruta y tiempo") -> Ver ruta y tiempo | AJ2: =IF(AI2="",HYPERLINK("https://www.google.com/search?q=site%3Ainstagram.com+El+Jard%C3%ADn+de+Ventas+bodas","Buscar en Instagram"),HYPERLINK("https://instagram.com/"&SUBSTITUTE(AI2,"@",""),AI2)) -> Buscar en Instagram
A3: 2 | B3: Real Fábrica de Tapices & El Puchero de Plata | C3: Espacio histórico con jardines (Patrimonio Nacional) | D3: Madrid – Retiro | E3: C/ Fuenterrabía 2, 28014 Madrid | F3: =ROUND(6371*2*ASIN(SQRT(SIN(RADIANS(AE3-Notas!$B$4)/2)^2+COS(RADIANS(Notas!$B$4))*COS(RADIANS(AE3))*SIN(RADIANS(AF3-Notas!$B$5)/2)^2)),1) -> 2.4 | G3: =IF(F3<=Notas!$B$6,"Sí","No") -> Sí | H3: Menú desde 138 €/invitado | I3: 138 | J3: =IF(ISNUMBER(I3),I3*Notas!$B$7,"") -> 16560 | L3: 450 | M3: Hasta 450 | N3: El Puchero de Plata (catering asociado al espacio) | O3: No (catering asociado) – confirmar | P3: Varias salas y zonas + jardines cuidados | Q3: Varios | R3: Sí (jardines) | S3: No consta – preguntar | T3: Sí (se puede montar la ceremonia en el lugar) | U3: No | V3: No consta | W3: No consta | X3: Fábrica de tapices s. XVIII en activo. Céntrico. | AA3: 4,9 (174) | AB3: +34 914 34 05 50 | AC3: https://www.bodas.net/fincas/real-fabrica-de-tapices-&-el-puchero-de-plata--e76351 | AD3: =HYPERLINK("https://www.google.com/maps/search/?api=1&query="&AE3&","&AF3,"Abrir mapa") -> Abrir mapa | AE3: 40.40615 | AF3: -3.6825436 | AG3: =ROUND(F3*Notas!$B$8/Notas!$B$9*60,0) -> 5 | AH3: =HYPERLINK("https://www.google.com/maps/dir/?api=1&origin=Calle+de+Ayala+71,+Madrid&destination="&AE3&","&AF3&"&travelmode=driving","Ver ruta y tiempo") -> Ver ruta y tiempo | AJ3: =IF(AI3="",HYPERLINK("https://www.google.com/search?q=site%3Ainstagram.com+Real+F%C3%A1brica+de+Tapices+++El+Puchero+de+Plata+bodas","Buscar en Instagram"),HYPERLINK("https://instagram.com/"&SUBSTITUTE(AI3,"@",""),AI3)) -> Buscar en Instagram
A4: 3 | B4: La Quinta by Madrid Catering | C4: Quinta / finca urbana | D4: Madrid – Hortaleza | E4: C/ de Belisana 17, 28043 Madrid | F4: =ROUND(6371*2*ASIN(SQRT(SIN(RADIANS(AE4-Notas!$B$4)/2)^2+COS(RADIANS(Notas!$B$4))*COS(RADIANS(AE4))*SIN(RADIANS(AF4-Notas!$B$5)/2)^2)),1) -> 3.9 | G4: =IF(F4<=Notas!$B$6,"Sí","No") -> Sí | H4: Menús 14–100 €/invitado según bodas.net (el tramo bajo será infantil/cóctel; pedir presupuesto) | J4: =IF(ISNUMBER(I4),I4*Notas!$B$7,"") | K4: 10 | L4: 165 | M4: 10–165 | N4: Madrid Catering (diseñan menú, decoración y coordinación) | O4: No (catering de la casa) | P4: Finca con jardín y espacios interiores; montaje y decoración personalizables | Q4: Consultar | R4: Sí (jardín) | S4: No consta – preguntar | T4: Consultar | U4: No | V4: No consta | W4: No consta | X4: Eventos a medida con coordinación integral el día de la boda. Opiniones destacan la flexibilidad. | Y4: 4.5 | Z4: 61 | AA4: — | AB4: +34 722 75 66 03 | AC4: https://www.bodas.net/salones-de-boda/la-quinta-by-madrid-catering--e252629 | AD4: =HYPERLINK("https://www.google.com/maps/search/?api=1&query="&AE4&","&AF4,"Abrir mapa") -> Abrir mapa | AE4: 40.458634 | AF4: -3.6553225 | AG4: =ROUND(F4*Notas!$B$8/Notas!$B$9*60,0) -> 8 | AH4: =HYPERLINK("https://www.google.com/maps/dir/?api=1&origin=Calle+de+Ayala+71,+Madrid&destination="&AE4&","&AF4&"&travelmode=driving","Ver ruta y tiempo") -> Ver ruta y tiempo | AJ4: =IF(AI4="",HYPERLINK("https://www.google.com/search?q=site%3Ainstagram.com+La+Quinta+by+Madrid+Catering+bodas","Buscar en Instagram"),HYPERLINK("https://instagram.com/"&SUBSTITUTE(AI4,"@",""),AI4)) -> Buscar en Instagram
A5: 4 | B5: Quinta de los Molinos by Elba | C5: Hotel con jardines (junto al parque Quinta de los Molinos) | D5: Madrid – San Blas | E5: C/ de Alcalá 476, 28027 Madrid | F5: =ROUND(6371*2*ASIN(SQRT(SIN(RADIANS(AE5-Notas!$B$4)/2)^2+COS(RADIANS(Notas!$B$4))*COS(RADIANS(AE5))*SIN(RADIANS(AF5-Notas!$B$5)/2)^2)),1) -> 4 | G5: =IF(F5<=Notas!$B$6,"Sí","No") -> Sí | H5: Menú desde 138 €/invitado | I5: 138 | J5: =IF(ISNUMBER(I5),I5*Notas!$B$7,"") -> 16560 | K5: 60 | M5: Desde 60 invitados (máx. no publicado) | N5: Cocina del hotel | O5: No (catering del hotel) | P5: Varias instalaciones: ceremonia, cóctel y banquete en espacios distintos; jardín y terraza | Q5: Varios | R5: Sí (jardín y terraza) | S5: Sí – habitaciones del hotel | T5: Sí (jardín) | U5: Sí (hotel) | V5: Sí (gestionan plazas) | W5: No consta | X5: Boda campestre sin salir de la ciudad; flexibles con menús, cócteles y horas de barra libre. | Y5: 4.4 | Z5: 28 | AA5: 4,8 (44) | AB5: +34 913 75 68 07 | AC5: https://www.bodas.net/fincas/quinta-de-los-molinos-by-elba--e109054 | AD5: =HYPERLINK("https://www.google.com/maps/search/?api=1&query="&AE5&","&AF5,"Abrir mapa") -> Abrir mapa | AE5: 40.439352 | AF5: -3.6315274 | AG5: =ROUND(F5*Notas!$B$8/Notas!$B$9*60,0) -> 8 | AH5: =HYPERLINK("https://www.google.com/maps/dir/?api=1&origin=Calle+de+Ayala+71,+Madrid&destination="&AE5&","&AF5&"&travelmode=driving","Ver ruta y tiempo") -> Ver ruta y tiempo | AJ5: =IF(AI5="",HYPERLINK("https://www.google.com/search?q=site%3Ainstagram.com+Quinta+de+los+Molinos+by+Elba+bodas","Buscar en Instagram"),HYPERLINK("https://instagram.com/"&SUBSTITUTE(AI5,"@",""),AI5)) -> Buscar en Instagram
A6: 5 | B6: Palacete / Complejo Duques de Pastrana | C6: Palacete s. XIX con jardines | D6: Madrid – Chamartín | E6: P.º de la Habana 208 / C/ Platerías 2, 28016 Madrid | F6: =ROUND(6371*2*ASIN(SQRT(SIN(RADIANS(AE6-Notas!$B$4)/2)^2+COS(RADIANS(Notas!$B$4))*COS(RADIANS(AE6))*SIN(RADIANS(AF6-Notas!$B$5)/2)^2)),1) -> 4.4 | G6: =IF(F6<=Notas!$B$6,"Sí","No") -> Sí | H6: No publicado (pedir presupuesto) | J6: =IF(ISNUMBER(I6),I6*Notas!$B$7,"") | L6: 740 | M6: Jardines del palacete: 220 banquete / 500 cóctel; otros jardines 500; Sala Polivalente 740 | N6: Vilaplana Catering (Compass Group), que gestiona los eventos del complejo | O6: No (catering del complejo) | P6: Palacete (Sala Roja 150, Balcones 125, Verde 110) + Sala Polivalente + salas de exposiciones + auditorio; 17 salas | Q6: Varios | R6: Sí (porche de columnas y 1.200 m² de jardines) | S6: Hay salas pequeñas en el palacete – preguntar | T6: Sí (jardines) | U6: No | V6: Sí | W6: No consta | X6: Monumento de Interés Cultural; metro Duque de Pastrana (L9) al lado. Ofrecen también wedding planner y decoración. Contacto: comercial@complejoduquesdepastrana.es | Y6: 4.4 | Z6: 912 | AA6: — | AB6: +34 913 53 61 51 | AC6: https://www.timeout.es/madrid/es/que-hacer/palacio-duques-de-pastrana | AD6: =HYPERLINK("https://www.google.com/maps/search/?api=1&query="&AE6&","&AF6,"Abrir mapa") -> Abrir mapa | AE6: 40.467403 | AF6: -3.6787017 | AG6: =ROUND(F6*Notas!$B$8/Notas!$B$9*60,0) -> 9 | AH6: =HYPERLINK("https://www.google.com/maps/dir/?api=1&origin=Calle+de+Ayala+71,+Madrid&destination="&AE6&","&AF6&"&travelmode=driving","Ver ruta y tiempo") -> Ver ruta y tiempo | AJ6: =IF(AI6="",HYPERLINK("https://www.google.com/search?q=site%3Ainstagram.com+Palacete+%2F+Complejo+Duques+de+Pastrana+bodas","Buscar en Instagram"),HYPERLINK("https://instagram.com/"&SUBSTITUTE(AI6,"@",""),AI6)) -> Buscar en Instagram
A7: 6 | B7: Café de Oriente Museo del Traje | C7: Museo con terrazas y jardín | D7: Madrid – Moncloa (Ciudad Universitaria) | E7: Av. de Juan de Herrera 2, 28040 Madrid | F7: =ROUND(6371*2*ASIN(SQRT(SIN(RADIANS(AE7-Notas!$B$4)/2)^2+COS(RADIANS(Notas!$B$4))*COS(RADIANS(AE7))*SIN(RADIANS(AF7-Notas!$B$5)/2)^2)),1) -> 4.7 | G7: =IF(F7<=Notas!$B$6,"Sí","No") -> Sí | H7: Menú desde 140 €/invitado (promoción todo incluido desde 170 €) | I7: 140 | J7: =IF(ISNUMBER(I7),I7*Notas!$B$7,"") -> 16800 | K7: 50 | L7: 700 | M7: 50–700 | N7: Café de Oriente / Alabardero Catering | O7: No (catering de la casa) | P7: Varios: Sala Oriente, Terraza Oriente, Terraza Balenciaga, espacio Cardenal Cisneros | Q7: Varios | R7: Sí (varias terrazas) | S7: No consta – preguntar | T7: Consultar | U7: No | V7: No consta | W7: No consta | X7: Buena opción para bodas tipo cóctel con puestos temáticos. | Y7: 4.2 | Z7: 2049 | AA7: 4,8 (57) | AB7: +34 915 50 20 55 | AC7: https://www.bodas.net/fincas/cafe-de-oriente-museo-del-traje--e47950 | AD7: =HYPERLINK("https://www.google.com/maps/search/?api=1&query="&AE7&","&AF7,"Abrir mapa") -> Abrir mapa | AE7: 40.439845 | AF7: -3.7294501 | AG7: =ROUND(F7*Notas!$B$8/Notas!$B$9*60,0) -> 9 | AH7: =HYPERLINK("https://www.google.com/maps/dir/?api=1&origin=Calle+de+Ayala+71,+Madrid&destination="&AE7&","&AF7&"&travelmode=driving","Ver ruta y tiempo") -> Ver ruta y tiempo | AJ7: =IF(AI7="",HYPERLINK("https://www.google.com/search?q=site%3Ainstagram.com+Caf%C3%A9+de+Oriente+Museo+del+Traje+bodas","Buscar en Instagram"),HYPERLINK("https://instagram.com/"&SUBSTITUTE(AI7,"@",""),AI7)) -> Buscar en Instagram
A8: 7 | B8: Casa de Burgos | C8: Castillo-pabellón con jardín (Casa de Campo) | D8: Madrid – Casa de Campo | E8: C/ Principal de Provincias 3, 28011 Madrid | F8: =ROUND(6371*2*ASIN(SQRT(SIN(RADIANS(AE8-Notas!$B$4)/2)^2+COS(RADIANS(Notas!$B$4))*COS(RADIANS(AE8))*SIN(RADIANS(AF8-Notas!$B$5)/2)^2)),1) -> 4.9 | G8: =IF(F8<=Notas!$B$6,"Sí","No") -> Sí | H8: Menú desde 100 €/invitado | I8: 100 | J8: =IF(ISNUMBER(I8),I8*Notas!$B$7,"") -> 12000 | K8: 50 | L8: 350 | M8: 50–350 (ficha de eventos: hasta 400 banquete / 630 cóctel) | N8: Grupo Araceli ("Casa de Burgos de Araceli") | O8: No (catering de la casa) | P8: Salón principal (450 m²) + salones Lavanda (60 m²) y Jazmín (50 m²) + patio porticado + jardín 800 m² | Q8: Varios | R8: Sí – jardín/terraza con vistas al Palacio Real y la Almudena | S8: 2 salones pequeños (Lavanda/Jazmín) – preguntar si se ceden a los novios | T8: Sí (jardín con vistas) | U8: No | V8: No consta | W8: No consta | X8: Réplica de castillo s. XIV construida en 1953-56 para la Feria del Campo. | Y8: 4.5 | Z8: 596 | AA8: 4,9 (201) | AB8: +34 914 64 40 77 | AC8: https://www.bodas.net/fincas/casa-de-burgos--e121847 | AD8: =HYPERLINK("https://www.google.com/maps/search/?api=1&query="&AE8&","&AF8,"Abrir mapa") -> Abrir mapa | AE8: 40.414464 | AF8: -3.7308012 | AG8: =ROUND(F8*Notas!$B$8/Notas!$B$9*60,0) -> 10 | AH8: =HYPERLINK("https://www.google.com/maps/dir/?api=1&origin=Calle+de+Ayala+71,+Madrid&destination="&AE8&","&AF8&"&travelmode=driving","Ver ruta y tiempo") -> Ver ruta y tiempo | AJ8: =IF(AI8="",HYPERLINK("https://www.google.com/search?q=site%3Ainstagram.com+Casa+de+Burgos+bodas","Buscar en Instagram"),HYPERLINK("https://instagram.com/"&SUBSTITUTE(AI8,"@",""),AI8)) -> Buscar en Instagram
A9: 8 | B9: La Masía de José Luis | C9: Finca urbana con jardín | D9: Madrid – Casa de Campo (Puerta del Ángel) | E9: P.º de la Puerta del Ángel 3, 28011 Madrid | F9: =ROUND(6371*2*ASIN(SQRT(SIN(RADIANS(AE9-Notas!$B$4)/2)^2+COS(RADIANS(Notas!$B$4))*COS(RADIANS(AE9))*SIN(RADIANS(AF9-Notas!$B$5)/2)^2)),1) -> 4.9 | G9: =IF(F9<=Notas!$B$6,"Sí","No") -> Sí | H9: Menú desde 140 €/invitado | I9: 140 | J9: =IF(ISNUMBER(I9),I9*Notas!$B$7,"") -> 16800 | K9: 60 | L9: 440 | M9: 60–440 | N9: Grupo José Luis (catering propio) | O9: No (catering de la casa) | P9: Varios: Zaguán, Invernadero, Salón Espejos (mesa imperial), carpa; 2.500 m² de jardín y terrazas | Q9: Varios | R9: Sí (jardín y terrazas) | S9: No consta – preguntar | T9: Consultar | U9: No | V9: No consta | W9: No consta | X9: Finca de 2.828 m² rodeada de vegetación. | Y9: 4.5 | Z9: 1105 | AA9: 4,9 (91) | AB9: +34 914 79 86 15 | AC9: https://www.bodas.net/fincas/la-masia-de-jose-luis--e3442 | AD9: =HYPERLINK("https://www.google.com/maps/search/?api=1&query="&AE9&","&AF9,"Abrir mapa") -> Abrir mapa | AE9: 40.415241 | AF9: -3.7311611 | AG9: =ROUND(F9*Notas!$B$8/Notas!$B$9*60,0) -> 10 | AH9: =HYPERLINK("https://www.google.com/maps/dir/?api=1&origin=Calle+de+Ayala+71,+Madrid&destination="&AE9&","&AF9&"&travelmode=driving","Ver ruta y tiempo") -> Ver ruta y tiempo | AJ9: =IF(AI9="",HYPERLINK("https://www.google.com/search?q=site%3Ainstagram.com+La+Mas%C3%ADa+de+Jos%C3%A9+Luis+bodas","Buscar en Instagram"),HYPERLINK("https://instagram.com/"&SUBSTITUTE(AI9,"@",""),AI9)) -> Buscar en Instagram
A10: 9 | B10: Club de Campo Villa de Madrid | C10: Club deportivo con jardines | D10: Madrid – Moncloa-Aravaca | E10: Ctra. de Castilla s/n, 28040 Madrid | F10: =ROUND(6371*2*ASIN(SQRT(SIN(RADIANS(AE10-Notas!$B$4)/2)^2+COS(RADIANS(Notas!$B$4))*COS(RADIANS(AE10))*SIN(RADIANS(AF10-Notas!$B$5)/2)^2)),1) -> 5.8 | G10: =IF(F10<=Notas!$B$6,"Sí","No") -> Sí | H10: Alquiler de espacio: Chalet del Golf 2.500 € (IVA incl.); otro espacio desde 1.000 € + IVA según invitados; + menú (pedir presupuesto) | J10: =IF(ISNUMBER(I10),I10*Notas!$B$7,"") | M10: No publicado | N10: Catering del club (cocina del chef Iván Sáez); en opiniones también Cavalier Catering | O10: No – no se admiten comida ni bebida del exterior | P10: 2 espacios: La Cristalera (Hípica) y el Chalet del Golf, con jardín y vistas a Madrid iluminado; carpas con proveedor del club | Q10: Varios | R10: Sí (jardín; vistas a Madrid) | S10: No consta – preguntar | T10: Consultar | U10: No | V10: Sí, dentro del club | W10: 4 h de barra libre incluidas (hora extra aparte) | X10: Dossier «Bodas 2026» del club: reserva = alquiler del espacio + contrato de catering con 25% de depósito; incluye decoración floral de mesas y degustación (6 personas en bodas de 100+); menú infantil 50 €; jamón con cortador en bodas de 150+. Descuentos para abonados. | Y10: 4.3 | Z10: 891 | AA10: — | AB10: — | AC10: https://www.ccvm.es/sites/default/files/users/user7/BODAS%202026.pdf | AD10: =HYPERLINK("https://www.google.com/maps/search/?api=1&query="&AE10&","&AF10,"Abrir mapa") -> Abrir mapa | AE10: 40.438728 | AF10: -3.742673 | AG10: =ROUND(F10*Notas!$B$8/Notas!$B$9*60,0) -> 11 | AH10: =HYPERLINK("https://www.google.com/maps/dir/?api=1&origin=Calle+de+Ayala+71,+Madrid&destination="&AE10&","&AF10&"&travelmode=driving","Ver ruta y tiempo") -> Ver ruta y tiempo | AJ10: =IF(AI10="",HYPERLINK("https://www.google.com/search?q=site%3Ainstagram.com+Club+de+Campo+Villa+de+Madrid+bodas","Buscar en Instagram"),HYPERLINK("https://instagram.com/"&SUBSTITUTE(AI10,"@",""),AI10)) -> Buscar en Instagram
A11: 10 | B11: Mirador del Olivar | C11: Club de golf con jardines (Olivar de la Hinojosa) | D11: Madrid – Barajas (Campo de las Naciones) | E11: Vía de Dublín s/n, 28042 Madrid | F11: =ROUND(6371*2*ASIN(SQRT(SIN(RADIANS(AE11-Notas!$B$4)/2)^2+COS(RADIANS(Notas!$B$4))*COS(RADIANS(AE11))*SIN(RADIANS(AF11-Notas!$B$5)/2)^2)),1) -> 7.2 | G11: =IF(F11<=Notas!$B$6,"Sí","No") -> Sí | H11: Menú desde 99 €/invitado | I11: 99 | J11: =IF(ISNUMBER(I11),I11*Notas!$B$7,"") -> 11880 | K11: 50 | L11: 520 | M11: 50–520 | N11: Restaurante del club | O11: No (catering de la casa) | P11: Salón + carpa exterior; ceremonia exterior o interior | Q11: Varios | R11: Sí (carpa, jardín y campo de golf para fotos) | S11: No consta – preguntar | T11: Sí (exterior e interior) | U11: No | V11: Sí | W11: No consta | X11: Vistas al campo de golf. Cerca del aeropuerto. | Y11: 4.1 | Z11: 83 | AA11: 4,9 (96) | AB11: — | AC11: https://www.bodas.net/fincas/mirador-del-olivar--e16700 | AD11: =HYPERLINK("https://www.google.com/maps/search/?api=1&query="&AE11&","&AF11,"Abrir mapa") -> Abrir mapa | AE11: 40.469352 | AF11: -3.6104488 | AG11: =ROUND(F11*Notas!$B$8/Notas!$B$9*60,0) -> 14 | AH11: =HYPERLINK("https://www.google.com/maps/dir/?api=1&origin=Calle+de+Ayala+71,+Madrid&destination="&AE11&","&AF11&"&travelmode=driving","Ver ruta y tiempo") -> Ver ruta y tiempo | AJ11: =IF(AI11="",HYPERLINK("https://www.google.com/search?q=site%3Ainstagram.com+Mirador+del+Olivar+bodas","Buscar en Instagram"),HYPERLINK("https://instagram.com/"&SUBSTITUTE(AI11,"@",""),AI11)) -> Buscar en Instagram
A12: 11 | B12: Club de Tiro de Madrid | C12: Finca en el Monte de El Pardo | D12: Madrid – El Pardo | E12: Ctra. Madrid-El Pardo M-605 km 1,2, 28035 Madrid | F12: =ROUND(6371*2*ASIN(SQRT(SIN(RADIANS(AE12-Notas!$B$4)/2)^2+COS(RADIANS(Notas!$B$4))*COS(RADIANS(AE12))*SIN(RADIANS(AF12-Notas!$B$5)/2)^2)),1) -> 8.9 | G12: =IF(F12<=Notas!$B$6,"Sí","No") -> Sí | H12: Menú 130–155 €/invitado | I12: 130 | J12: =IF(ISNUMBER(I12),I12*Notas!$B$7,"") -> 15600 | K12: 80 | L12: 600 | M12: 80–600 | N12: Life Gourmet / Ramón Freixa Catering (cocina propia) | O12: No – exclusivo (no se alquila solo el espacio) | P12: 2 espacios independientes (Colonial e Invernadero), cada uno con parking, entrada y jardines propios; carpa y zona de baile | Q12: Varios | R12: Sí (terraza, jardines y carpa) | S12: Hay baño/zona de novia (según opiniones) – confirmar sala | T12: Sí, ceremonia civil en jardines | U12: No | V12: Sí | W12: Hasta las 05:00 · 1 evento al día | X12: Exclusividad también de música. Barra libre incluida (con límite de hora). Tarta propia permitida con registro sanitario. 6 Wedding Awards. | Y12: 4.3 | Z12: 1436 | AA12: 4,8 (184) | AB12: +34 913 16 11 69 | AC12: https://www.bodas.net/fincas/club-de-tiro--e81609 | AD12: =HYPERLINK("https://www.google.com/maps/search/?api=1&query="&AE12&","&AF12,"Abrir mapa") -> Abrir mapa | AE12: 40.488892 | AF12: -3.7435091 | AG12: =ROUND(F12*Notas!$B$8/Notas!$B$9*60,0) -> 17 | AH12: =HYPERLINK("https://www.google.com/maps/dir/?api=1&origin=Calle+de+Ayala+71,+Madrid&destination="&AE12&","&AF12&"&travelmode=driving","Ver ruta y tiempo") -> Ver ruta y tiempo | AJ12: =IF(AI12="",HYPERLINK("https://www.google.com/search?q=site%3Ainstagram.com+Club+de+Tiro+de+Madrid+bodas","Buscar en Instagram"),HYPERLINK("https://instagram.com/"&SUBSTITUTE(AI12,"@",""),AI12)) -> Buscar en Instagram
A13: 12 | B13: Fuentearcos | C13: Finca-restaurante con jardines | D13: Madrid – Vicálvaro | E13: Ctra. Vicálvaro a Rivas km 2, 28052 Madrid | F13: =ROUND(6371*2*ASIN(SQRT(SIN(RADIANS(AE13-Notas!$B$4)/2)^2+COS(RADIANS(Notas!$B$4))*COS(RADIANS(AE13))*SIN(RADIANS(AF13-Notas!$B$5)/2)^2)),1) -> 9.5 | G13: =IF(F13<=Notas!$B$6,"Sí","No") -> Sí | H13: Menú desde 120 €/invitado | I13: 120 | J13: =IF(ISNUMBER(I13),I13*Notas!$B$7,"") -> 14400 | K13: 20 | L13: 350 | M13: 20–350 | N13: Cocina propia del restaurante | O13: No (catering de la casa) – confirmar | P13: Varios espacios (p. ej. Espacio/Salón Arcos con cristalera) y jardines | Q13: Varios | R13: Sí (jardines) | S13: No consta – preguntar | T13: Sí (Jardín Arcos) | U13: No | V13: Sí | W13: No consta | X13: Apta para bodas muy pequeñas (desde 20). 5 promociones activas en bodas.net. | Y13: 4.4 | Z13: 2647 | AA13: 4,9 (405) | AB13: +34 917 76 55 17 | AC13: https://www.bodas.net/fincas/fuentearcos--e1946 | AD13: =HYPERLINK("https://www.google.com/maps/search/?api=1&query="&AE13&","&AF13,"Abrir mapa") -> Abrir mapa | AE13: 40.392734 | AF13: -3.5741806 | AG13: =ROUND(F13*Notas!$B$8/Notas!$B$9*60,0) -> 19 | AH13: =HYPERLINK("https://www.google.com/maps/dir/?api=1&origin=Calle+de+Ayala+71,+Madrid&destination="&AE13&","&AF13&"&travelmode=driving","Ver ruta y tiempo") -> Ver ruta y tiempo | AJ13: =IF(AI13="",HYPERLINK("https://www.google.com/search?q=site%3Ainstagram.com+Fuentearcos+bodas","Buscar en Instagram"),HYPERLINK("https://instagram.com/"&SUBSTITUTE(AI13,"@",""),AI13)) -> Buscar en Instagram
A14: 13 | B14: Finca Solimpar | C14: Finca con hotel | D14: Leganés | E14: Ctra. de Toledo A-42 km 8, 28916 Leganés | F14: =ROUND(6371*2*ASIN(SQRT(SIN(RADIANS(AE14-Notas!$B$4)/2)^2+COS(RADIANS(Notas!$B$4))*COS(RADIANS(AE14))*SIN(RADIANS(AF14-Notas!$B$5)/2)^2)),1) -> 9.7 | G14: =IF(F14<=Notas!$B$6,"Sí","No") -> Sí | H14: Menú desde 90 €/invitado (bodas.net) | I14: 90 | J14: =IF(ISNUMBER(I14),I14*Notas!$B$7,"") -> 10800 | K14: 50 | L14: 300 | M14: 50–300 o más (bodas.net); banquete hasta ~400 según ficha de eventos | N14: Cocina propia del restaurante | O14: No (catering de la casa) | P14: Varios salones interiores modulares con acceso directo a jardines | Q14: Varios | R14: Sí (jardines con césped) | S14: Sí – habitaciones del hotel | T14: Sí (jardín) | U14: Sí (hotel, 32 habitaciones) | V14: Sí | W14: No consta | X14: A 10 min del centro por la A-42. | Y14: 4.4 | Z14: 2451 | AA14: 4,7 (350) | AB14: +34 913 41 91 25 | AC14: https://www.bodas.net/fincas/finca-solimpar--e2670 | AD14: =HYPERLINK("https://www.google.com/maps/search/?api=1&query="&AE14&","&AF14,"Abrir mapa") -> Abrir mapa | AE14: 40.348365 | AF14: -3.7242015 | AG14: =ROUND(F14*Notas!$B$8/Notas!$B$9*60,0) -> 19 | AH14: =HYPERLINK("https://www.google.com/maps/dir/?api=1&origin=Calle+de+Ayala+71,+Madrid&destination="&AE14&","&AF14&"&travelmode=driving","Ver ruta y tiempo") -> Ver ruta y tiempo | AJ14: =IF(AI14="",HYPERLINK("https://www.google.com/search?q=site%3Ainstagram.com+Finca+Solimpar+bodas","Buscar en Instagram"),HYPERLINK("https://instagram.com/"&SUBSTITUTE(AI14,"@",""),AI14)) -> Buscar en Instagram
A15: 14 | B15: El Jardín de Somontes (Eventos Somontes) | C15: Jardín para eventos con piscina y carpa | D15: Madrid – El Pardo (Somontes) | E15: Ctra. Madrid-El Pardo km 3,4, 28035 Madrid | F15: =ROUND(6371*2*ASIN(SQRT(SIN(RADIANS(AE15-Notas!$B$4)/2)^2+COS(RADIANS(Notas!$B$4))*COS(RADIANS(AE15))*SIN(RADIANS(AF15-Notas!$B$5)/2)^2)),1) -> 9.7 | G15: =IF(F15<=Notas!$B$6,"Sí","No") -> Sí | H15: No publicado (depende del catering elegido) | J15: =IF(ISNUMBER(I15),I15*Notas!$B$7,"") | K15: 150 | L15: 400 | M15: 150–400 (recargo de 20 €/comensal por debajo de 150) | N15: Trabaja con caterings colaboradores (Catering Mallorca, Artigot Catering) | O15: Lista de caterings (no libre del todo) – pago fijo de 900 € si se elige Mallorca | P15: Jardín (ceremonia y cóctel) + espacio interior (banquete) + gran carpa junto a la piscina (barra libre) | Q15: Varios | R15: Sí (jardín, carpa y piscina) | S15: No consta – preguntar | T15: Sí, ceremonia civil en el jardín | U15: No | V15: No consta | W15: No consta | X15: Mínimo alto (150 invitados). Una de las pocas opciones dentro del radio que no ata a un único catering. | Y15: 4.5 | Z15: 19 | AA15: — | AB15: +34 600 51 65 61 | AC15: https://www.bodas.net/restaurantes/el-jardin-de-somontes--e193863 | AD15: =HYPERLINK("https://www.google.com/maps/search/?api=1&query="&AE15&","&AF15,"Abrir mapa") -> Abrir mapa | AE15: 40.48961 | AF15: -3.756931 | AG15: =ROUND(F15*Notas!$B$8/Notas!$B$9*60,0) -> 19 | AH15: =HYPERLINK("https://www.google.com/maps/dir/?api=1&origin=Calle+de+Ayala+71,+Madrid&destination="&AE15&","&AF15&"&travelmode=driving","Ver ruta y tiempo") -> Ver ruta y tiempo | AJ15: =IF(AI15="",HYPERLINK("https://www.google.com/search?q=site%3Ainstagram.com+El+Jard%C3%ADn+de+Somontes++Eventos+Somontes+bodas","Buscar en Instagram"),HYPERLINK("https://instagram.com/"&SUBSTITUTE(AI15,"@",""),AI15)) -> Buscar en Instagram
A16: 15 | B16: La Casa de Mónico | C16: Finca solariega (1946) con jardín inglés | D16: Madrid – Aravaca | E16: C/ Cabeza de Manzaneda 105 (A-6 km 9,5), 28023 Madrid | F16: =ROUND(6371*2*ASIN(SQRT(SIN(RADIANS(AE16-Notas!$B$4)/2)^2+COS(RADIANS(Notas!$B$4))*COS(RADIANS(AE16))*SIN(RADIANS(AF16-Notas!$B$5)/2)^2)),1) -> 9.8 | G16: =IF(F16<=Notas!$B$6,"Sí","No") -> Sí | H16: Menú desde 185 €/invitado | I16: 185 | J16: =IF(ISNUMBER(I16),I16*Notas!$B$7,"") -> 22200 | K16: 50 | L16: 600 | M16: 50–600 (ficha de eventos: 670 interior / 2.500 exterior) | N16: Mónico Catering (Grupo Mónico) | O16: No – exclusivo (condiciones especiales si no se llega al mínimo) | P16: 5 salas/espacios + jardín inglés de 30.000 m² | Q16: Varios | R16: Sí (jardines) | S16: No consta – preguntar | T16: Sí (jardín) | U16: No | V16: Sí (380 plazas) | W16: No consta | X16: Reformada por el estudio de Luisa Olazábal. La más cara de las que publican precio. | Y16: 4.5 | Z16: 1203 | AA16: 4,9 (213) | AB16: +34 913 57 32 55 | AC16: https://www.bodas.net/fincas/la-casa-de-monico--e2021 | AD16: =HYPERLINK("https://www.google.com/maps/search/?api=1&query="&AE16&","&AF16,"Abrir mapa") -> Abrir mapa | AE16: 40.465202 | AF16: -3.780812 | AG16: =ROUND(F16*Notas!$B$8/Notas!$B$9*60,0) -> 19 | AH16: =HYPERLINK("https://www.google.com/maps/dir/?api=1&origin=Calle+de+Ayala+71,+Madrid&destination="&AE16&","&AF16&"&travelmode=driving","Ver ruta y tiempo") -> Ver ruta y tiempo | AJ16: =IF(AI16="",HYPERLINK("https://www.google.com/search?q=site%3Ainstagram.com+La+Casa+de+M%C3%B3nico+bodas","Buscar en Instagram"),HYPERLINK("https://instagram.com/"&SUBSTITUTE(AI16,"@",""),AI16)) -> Buscar en Instagram
A17: 16 | B17: Finca La Gaivota | C17: Finca con casa señorial (años 40) | D17: Madrid – Aravaca | E17: C/ Ardales s/n, 28023 Madrid | F17: =ROUND(6371*2*ASIN(SQRT(SIN(RADIANS(AE17-Notas!$B$4)/2)^2+COS(RADIANS(Notas!$B$4))*COS(RADIANS(AE17))*SIN(RADIANS(AF17-Notas!$B$5)/2)^2)),1) -> 9.8 | G17: =IF(F17<=Notas!$B$6,"Sí","No") -> Sí | H17: No publicado (pedir presupuesto) | J17: =IF(ISNUMBER(I17),I17*Notas!$B$7,"") | L17: 500 | M17: Hasta ~500 (prensa); pradera >1.000 m² para banquetes | N17: Isabel Maestre Catering | O17: No (catering asociado) – confirmar | P17: Casa señorial + carpa-invernadero acristalado + pradera + piscina; ~10.000 m² de jardines de Fernando Caruncho | Q17: Varios | R17: Sí (jardines, pradera y terraza) | S17: No consta – preguntar | T17: Sí (jardín) | U17: No | V17: No consta | W17: No consta | X17: A 8 min del centro. Invernadero como plan B si llueve. | Y17: 4.4 | Z17: 193 | AA17: — | AB17: +34 650 85 13 10 | AC17: https://www.salir.com/finca-la-gaivota-madrid-neg-141910.html | AD17: =HYPERLINK("https://www.google.com/maps/search/?api=1&query="&AE17&","&AF17,"Abrir mapa") -> Abrir mapa | AE17: 40.461983 | AF17: -3.7827754 | AG17: =ROUND(F17*Notas!$B$8/Notas!$B$9*60,0) -> 19 | AH17: =HYPERLINK("https://www.google.com/maps/dir/?api=1&origin=Calle+de+Ayala+71,+Madrid&destination="&AE17&","&AF17&"&travelmode=driving","Ver ruta y tiempo") -> Ver ruta y tiempo | AJ17: =IF(AI17="",HYPERLINK("https://www.google.com/search?q=site%3Ainstagram.com+Finca+La+Gaivota+bodas","Buscar en Instagram"),HYPERLINK("https://instagram.com/"&SUBSTITUTE(AI17,"@",""),AI17)) -> Buscar en Instagram
